<?xml version="1.0" ?>
<!-- =================================================================================== -->
<!-- |    This document was autogenerated by xacro from abb_irb120.urdf.xacro              | -->
<!-- |    EDITING THIS FILE BY HAND IS NOT RECOMMENDED                                 | -->
<!-- =================================================================================== -->
<!-- 

# ===================================== COPYRIGHT ===================================== #
#                                                                                       #
#  IFRA (Intelligent Flexible Robotics and Assembly) Group, CRANFIELD UNIVERSITY        #
#  Created on behalf of the IFRA Group at Cranfield University, United Kingdom          #
#  E-mail: IFRA@cranfield.ac.uk                                                         #
#                                                                                       #
#  Licensed under the Apache-2.0 License.                                               #
#  You may not use this file except in compliance with the License.                     #
#  You may obtain a copy of the License at: http://www.apache.org/licenses/LICENSE-2.0  #
#                                                                                       #
#  Unless required by applicable law or agreed to in writing, software distributed      #
#  under the License is distributed on an "as-is" basis, without warranties or          #
#  conditions of any kind, either express or implied. See the License for the specific  #
#  language governing permissions and limitations under the License.                    #
#                                                                                       #
#  IFRA Group - Cranfield University                                                    #
#  AUTHORS: Mikel Bueno Viso - Mikel.Bueno-Viso@cranfield.ac.uk                         #
#           Dr. Seemal Asif  - s.asif@cranfield.ac.uk                                   #
#           Prof. Phil Webb  - p.f.webb@cranfield.ac.uk                                 #
#                                                                                       #
#  Date: April, 2023.                                                                   #
#                                                                                       #
# ===================================== COPYRIGHT ===================================== #

# ======= CITE OUR WORK ======= #
# You can cite our work with the following statement:
# IFRA-Cranfield (2023) ROS 2 Sim-to-Real Robot Control. URL: https://github.com/IFRA-Cranfield/ros2_SimRealRobotControl.

-->
<robot name="abb_irb120" xmlns:xacro="http://ros.org/wiki/xacro">
  <!-- Arguments -->
  <xacro:arg name="use_fake_hardware" default="true"/>
  <xacro:property name="use_fake_hardware" value="$(arg use_fake_hardware)"/> <!-- Not implemented, TODO. -->
  <xacro:arg name="rws_ip" default="192.168.125.12"/>
  <xacro:property name="rws_ip" value="$(arg rws_ip)"/>
  <xacro:arg name="rws_port" default="80"/>
  <xacro:property name="rws_port" value="$(arg rws_port)"/>
  <xacro:arg name="configure_via_rws" default="true"/>
  <xacro:property name="configure_via_rws" value="$(arg configure_via_rws)"/>

  <!-- Conversion were obtained from http://www.e-paint.co.uk/Lab_values.asp
       unless otherwise stated. -->

  <!-- Transmissions. -->
  <transmission name="abb_irb120_joint1_trans">
    <type>transmission_interface/SimpleTransmission</type>
    <joint name="joint_1">
      <hardwareInterface>hardware_interface/PositionJointInterface</hardwareInterface>
    </joint>
    <actuator name="abb_irb120_joint1_motor">
      <mechanicalReduction>1</mechanicalReduction>
    </actuator>
  </transmission>
  <transmission name="abb_irb120_joint2_trans">
    <type>transmission_interface/SimpleTransmission</type>
    <joint name="joint_2">
      <hardwareInterface>hardware_interface/PositionJointInterface</hardwareInterface>
    </joint>
    <actuator name="abb_irb120_joint2_motor">
      <mechanicalReduction>1</mechanicalReduction>
    </actuator>
  </transmission>
  <transmission name="abb_irb120_joint3_trans">
    <type>transmission_interface/SimpleTransmission</type>
    <joint name="joint_3">
      <hardwareInterface>hardware_interface/PositionJointInterface</hardwareInterface>
    </joint>
    <actuator name="abb_irb120_joint3_motor">
      <mechanicalReduction>1</mechanicalReduction>
    </actuator>
  </transmission>
  <transmission name="abb_irb120_joint4_trans">
    <type>transmission_interface/SimpleTransmission</type>
    <joint name="joint_4">
      <hardwareInterface>hardware_interface/PositionJointInterface</hardwareInterface>
    </joint>
    <actuator name="abb_irb120_joint4_motor">
      <mechanicalReduction>1</mechanicalReduction>
    </actuator>
  </transmission>
  <transmission name="abb_irb120_joint5_trans">
    <type>transmission_interface/SimpleTransmission</type>
    <joint name="joint_5">
      <hardwareInterface>hardware_interface/PositionJointInterface</hardwareInterface>
    </joint>
    <actuator name="abb_irb120_joint5_motor">
      <mechanicalReduction>1</mechanicalReduction>
    </actuator>
  </transmission>
  <transmission name="abb_irb120_joint6_trans">
    <type>transmission_interface/SimpleTransmission</type>
    <joint name="joint_6">
      <hardwareInterface>hardware_interface/PositionJointInterface</hardwareInterface>
    </joint>
    <actuator name="abb_irb120_joint6_motor">
      <mechanicalReduction>1</mechanicalReduction>
    </actuator>
  </transmission>

  <!-- 3. Load ROS2_CONTROL: -->
  <ros2_control name="ABBMultiInterfaceHardware" type="system">
    <hardware>
      <plugin>abb_hardware_interface/ABBSystemHardware</plugin>
      <param name="configure_via_rws">${configure_via_rws}</param>
      <param name="rws_port">${rws_port}</param>
      <param name="rws_ip">${rws_ip}</param> <!-- Changed from "robot_ip" to rws_ip. -->
      <param name="egm_port">6511</param>
    </hardware>

    <!-- Set joint min/max vals. -->
    <!-- abb_irb120_joint1 -->
    <joint name="joint_1">
      <command_interface name="position">
        <param name="min">-2.87979</param>
        <param name="max">2.87979</param>
      </command_interface>
      <command_interface name="velocity">
        <param name="min">-4.36332</param>
        <param name="max">4.36332</param>
      </command_interface>
      <state_interface name="position">
        <param name="initial_value">0.0</param>
      </state_interface>
      <state_interface name="velocity"/>
    </joint>
    <!-- abb_irb120_joint2 -->
    <joint name="joint_2">
      <command_interface name="position">
        <param name="min">-1.91986</param>
        <param name="max">1.91986</param>
      </command_interface>
      <command_interface name="velocity">
        <param name="min">-4.36332</param>
        <param name="max">4.36332</param>
      </command_interface>
      <state_interface name="position">
        <param name="initial_value">0.0</param>
      </state_interface>
      <state_interface name="velocity"/>
    </joint>
    <!-- abb_irb120_joint3 -->
    <joint name="joint_3">
      <command_interface name="position">
        <param name="min">-1.91986</param>
        <param name="max">1.22173</param>
      </command_interface>
      <command_interface name="velocity">
        <param name="min">-4.36332</param>
        <param name="max">4.36332</param>
      </command_interface>
      <state_interface name="position">
        <param name="initial_value">0.0</param>
      </state_interface>
      <state_interface name="velocity"/>
    </joint>
    <!-- abb_irb120_joint4 -->
    <joint name="joint_4">
      <command_interface name="position">
        <param name="min">-2.79253</param>
        <param name="max">2.79253</param>
      </command_interface>
      <command_interface name="velocity">
        <param name="min">-5.58505</param>
        <param name="max">5.58505</param>
      </command_interface>
      <state_interface name="position">
        <param name="initial_value">0.0</param>
      </state_interface>
      <state_interface name="velocity"/>
    </joint>
    <!-- abb_irb120_joint5 -->
    <joint name="joint_5">
      <command_interface name="position">
        <param name="min">-2.00</param> <!-- Joint5 limits lowered to +-2rad -->
        <param name="max">2.00</param>
      </command_interface>
      <command_interface name="velocity">
        <param name="min">-5.58505</param>
        <param name="max">5.58505</param>
      </command_interface>
      <state_interface name="position">
        <param name="initial_value">1.570796</param>
      </state_interface>
      <state_interface name="velocity"/>
    </joint>
    <!-- abb_irb120_joint6 -->
    <joint name="joint_6">
      <command_interface name="position">
        <param name="min">-6.98132</param>
        <param name="max">6.98132</param>
      </command_interface>
      <command_interface name="velocity">
        <param name="min">-7.33038</param>
        <param name="max">7.33038</param>
      </command_interface>
      <state_interface name="position">
        <param name="initial_value">0.0</param>
      </state_interface>
      <state_interface name="velocity"/>
    </joint>
  </ros2_control>

  <gazebo reference="base_link">
    <selfCollide>false</selfCollide>
  </gazebo>
  <gazebo reference="link_1">
    <selfCollide>false</selfCollide>
  </gazebo>
  <gazebo reference="link_2">
    <selfCollide>false</selfCollide>
  </gazebo>
  <gazebo reference="link_3">
    <selfCollide>false</selfCollide>
  </gazebo>
  <gazebo reference="link_4">
    <selfCollide>false</selfCollide>
  </gazebo>
  <gazebo reference="link_5">
    <selfCollide>false</selfCollide>
  </gazebo>
  <gazebo reference="link_6">
    <selfCollide>false</selfCollide>
  </gazebo>
  <gazebo reference="end_effector_frame_fixed_joint">
    <preserveFixedJoint>true</preserveFixedJoint>
    <!-- For compatibility with SDFormat < 4.4 -->
    <disableFixedJointLumping>true</disableFixedJointLumping>
  </gazebo>
  <!-- ***** ABB-abb_irb120 ROBOT .urdf SERIAL CHAIN ***** -->
  <!-- Link list: -->
  <!-- base_link -->
  <link name="base_link">
    <inertial>
      <mass value="6.215"/>
      <origin rpy="0 0 0" xyz="-0.04204 8.01E-05 0.07964"/>
      <inertia ixx="0.0247272" ixy="-8.0784E-05" ixz="0.00130902" iyy="0.0491285" iyz="-8.0419E-06" izz="0.0472376"/>
    </inertial>
    <visual>
      <origin rpy="0 0 0" xyz="0 0 0"/>
      <geometry>
        <mesh filename="package://abb_irb120_support/meshes/visual/base_link.dae"/>
      </geometry>
      <material name="">
        <color rgba="0.7372549 0.3490196 0.1607843 1"/>
      </material>
    </visual>
    <collision>
      <origin rpy="0 0 0" xyz="0 0 0"/>
      <geometry>
        <mesh filename="package://abb_irb120_support/meshes/collision/base_link.stl"/>
      </geometry>
      <material name="">
        <color rgba="1 1 0 1"/>
      </material>
    </collision>
  </link>
  <!-- link_1 -->
  <link name="link_1">
    <inertial>
      <mass value="3.067"/>
      <origin rpy="0 0 0" xyz="9.77E-05 -0.00012 0.23841"/>
      <inertia ixx="0.0142175" ixy="-1.28579E-05" ixz="-2.31364E-05" iyy="0.0144041" iyz="1.93404E-05" izz="0.0104533"/>
    </inertial>
    <visual>
      <origin rpy="0 0 0" xyz="0 0 0"/>
      <geometry>
        <mesh filename="package://abb_irb120_support/meshes/visual/link_1.dae"/>
      </geometry>
      <material name="">
        <color rgba="0.7372549 0.3490196 0.1607843 1"/>
      </material>
    </visual>
    <collision>
      <origin rpy="0 0 0" xyz="0 0 0"/>
      <geometry>
        <mesh filename="package://abb_irb120_support/meshes/collision/link_1.stl"/>
      </geometry>
      <material name="">
        <color rgba="1 1 0 1"/>
      </material>
    </collision>
  </link>
  <!-- link_2 -->
  <link name="link_2">
    <inertial>
      <mass value="3.909"/>
      <origin rpy="0 0 0" xyz="0.00078 -0.00212 0.10124"/>
      <inertia ixx="0.0603111" ixy="9.83431E-06" ixz="5.72407E-05" iyy="0.041569" iyz="-0.00050497" izz="0.0259548"/>
    </inertial>
    <visual>
      <origin rpy="0 0 0" xyz="0 0 0"/>
      <geometry>
        <mesh filename="package://abb_irb120_support/meshes/visual/link_2.dae"/>
      </geometry>
      <material name="">
        <color rgba="0.7372549 0.3490196 0.1607843 1"/>
      </material>
    </visual>
    <collision>
      <origin rpy="0 0 0" xyz="0 0 0"/>
      <geometry>
        <mesh filename="package://abb_irb120_support/meshes/collision/link_2.stl"/>
      </geometry>
      <material name="">
        <color rgba="1 1 0 1"/>
      </material>
    </collision>
  </link>
  <!-- link_3 -->
  <link name="link_3">
    <inertial>
      <mass value="2.944"/>
      <origin rpy="0 0 0" xyz="0.02281 0.00106 0.05791"/>
      <inertia ixx="0.00835606" ixy="-8.01545E-05" ixz="0.00142884" iyy="0.016713" iyz="-0.000182227" izz="0.0126984"/>
    </inertial>
    <visual>
      <origin rpy="0 0 0" xyz="0 0 0"/>
      <geometry>
        <mesh filename="package://abb_irb120_support/meshes/visual/link_3.dae"/>
      </geometry>
      <material name="">
        <color rgba="0.7372549 0.3490196 0.1607843 1"/>
      </material>
    </visual>
    <collision>
      <origin rpy="0 0 0" xyz="0 0 0"/>
      <geometry>
        <mesh filename="package://abb_irb120_support/meshes/collision/link_3.stl"/>
      </geometry>
      <material name="">
        <color rgba="1 1 0 1"/>
      </material>
    </collision>
  </link>
  <!-- link_4 -->
  <link name="link_4">
    <inertial>
      <mass value="1.328"/>
      <origin rpy="0 0 0" xyz="0.2247 0.00015 0.00041"/>
      <inertia ixx="0.00284661" ixy="-2.12765E-05" ixz="-1.6435E-05" iyy="0.00401346" iyz="1.31336E-05" izz="0.0052535"/>
    </inertial>
    <visual>
      <origin rpy="0 0 0" xyz="0 0 0"/>
      <geometry>
        <mesh filename="package://abb_irb120_support/meshes/visual/link_4.dae"/>
      </geometry>
      <material name="">
        <color rgba="0.7372549 0.3490196 0.1607843 1"/>
      </material>
    </visual>
    <collision>
      <origin rpy="0 0 0" xyz="0 0 0"/>
      <geometry>
        <mesh filename="package://abb_irb120_support/meshes/collision/link_4.stl"/>
      </geometry>
      <material name="">
        <color rgba="1 1 0 1"/>
      </material>
    </collision>
  </link>
  <!-- link_5 -->
  <link name="link_5">
    <inertial>
      <mass value="0.546"/>
      <origin rpy="0 0 0" xyz="-0.00109 3.68E-05 6.22E-05"/>
      <inertia ixx="0.000404891" ixy="1.61943E-06" ixz="8.46805E-07" iyy="0.000892825" iyz="-1.51792E-08" izz="0.000815468"/>
    </inertial>
    <visual>
      <origin rpy="0 0 0" xyz="0 0 0"/>
      <geometry>
        <mesh filename="package://abb_irb120_support/meshes/visual/link_5.dae"/>
      </geometry>
      <material name="">
        <color rgba="0.7372549 0.3490196 0.1607843 1"/>
      </material>
    </visual>
    <collision>
      <origin rpy="0 0 0" xyz="0 0 0"/>
      <geometry>
        <mesh filename="package://abb_irb120_support/meshes/collision/link_5.stl"/>
      </geometry>
      <material name="">
        <color rgba="1 1 0 1"/>
      </material>
    </collision>
  </link>
  <!-- link_6 -->
  <link name="link_6">
    <inertial>
      <mass value="0.137"/>
      <origin rpy="0 0 0" xyz="-0.00706 -0.00017 -1.32E-06"/>
      <inertia ixx="0.001" ixy="0" ixz="0" iyy="0.001" iyz="0" izz="0.001"/>
    </inertial>
    <visual>
      <origin rpy="0 0 0" xyz="0 0 0"/>
      <geometry>
        <mesh filename="package://abb_irb120_support/meshes/visual/link_6.dae"/>
      </geometry>
      <material name="">
        <color rgba="0.1882353 0.1960784 0.2039216 1"/>
      </material>
    </visual>
    <collision>
      <origin rpy="0 0 0" xyz="0 0 0"/>
      <geometry>
        <mesh filename="package://abb_irb120_support/meshes/collision/link_6.stl"/>
      </geometry>
      <material name="">
        <color rgba="1 1 0 1"/>
      </material>
    </collision>
  </link>
  <!-- end of link list -->
  <!-- Joint list: -->
  <!-- joint_1 -->
  <joint name="joint_1" type="revolute">
    <origin rpy="0 0 0" xyz="0 0 0"/>
    <parent link="base_link"/>
    <child link="link_1"/>
    <limit effort="1000" lower="-2.87979" upper="2.87979" velocity="4.36332"/>
    <axis xyz="0 0 1"/>
    <dynamics damping="50.0" friction="1.0"/>
  </joint>
  <!-- joint_2 -->
  <joint name="joint_2" type="revolute">
    <origin rpy="0 0 0" xyz="0 0 0.29"/>
    <parent link="link_1"/>
    <child link="link_2"/>
    <limit effort="1000" lower="-1.91986" upper="1.91986" velocity="4.36332"/>
    <axis xyz="0 1 0"/>
    <dynamics damping="50.0" friction="1.0"/>
  </joint>
  <!-- joint_3 -->
  <joint name="joint_3" type="revolute">
    <origin rpy="0 0 0" xyz="0 0 0.27"/>
    <parent link="link_2"/>
    <child link="link_3"/>
    <limit effort="1000" lower="-1.91986" upper="1.22173" velocity="4.36332"/>
    <axis xyz="0 1 0"/>
    <dynamics damping="10.0" friction="1.0"/>
  </joint>
  <!-- joint_4 -->
  <joint name="joint_4" type="revolute">
    <origin rpy="0 0 0" xyz="0 0 0.07"/>
    <parent link="link_3"/>
    <child link="link_4"/>
    <limit effort="1000" lower="-2.79253" upper="2.79253" velocity="5.58505"/>
    <axis xyz="1 0 0"/>
    <dynamics damping="5.0" friction="1.0"/>
  </joint>
  <!-- joint_5 -->
  <joint name="joint_5" type="revolute">
    <origin rpy="0 0 0" xyz="0.302 0 0"/>
    <parent link="link_4"/>
    <child link="link_5"/>
    <limit effort="1000" lower="-2.094395" upper="2.094395" velocity="5.58505"/>
    <axis xyz="0 1 0"/>
    <dynamics damping="2.0" friction="1.0"/>
  </joint>
  <!-- joint_6 -->
  <joint name="joint_6" type="revolute">
    <origin rpy="0 0 0" xyz="0.072 0 0"/>
    <parent link="link_5"/>
    <child link="link_6"/>
    <limit effort="1000" lower="-6.98132" upper="6.98132" velocity="7.33038"/>
    <axis xyz="1 0 0"/>
    <dynamics damping="1.0" friction="1.0"/>
  </joint>
  <!-- end of joint list -->
  <!-- ROS-Industrial 'base' frame: base_link to ABB World Coordinates transform -->
  <link name="base"/>
  <joint name="base_link-base" type="fixed">
    <origin rpy="0 0 0" xyz="0 0 0"/>
    <parent link="base_link"/>
    <child link="base"/>
  </joint>
  <!-- ROS-Industrial 'flange' frame: attachment point for EEF models -->
  <link name="flange"/>
  <joint name="joint_6-flange" type="fixed">
    <origin rpy="0 0 0" xyz="0 0 0"/>
    <parent link="link_6"/>
    <child link="flange"/>
  </joint>
  <!-- ROS-Industrial 'tool0' frame: all-zeros tool frame -->
  <link name="tool0"/>
  <joint name="link_6-tool0" type="fixed">
    <origin rpy="0 1.5707963267948966 0" xyz="0 0 0"/>
    <parent link="flange"/>
    <child link="tool0"/>
  </joint>

  <!-- Gazebo simulation thing with controller config, comment if needed. -->
   <!-- <plugin filename="libgazebo_ros2_control.so" name="gazebo_ros2_control">
      <robot_sim_type>gazebo_ros2_control/GazeboSystem</robot_sim_type>
        IRB 120 controller
      <parameters>package://abb_irb120_support/config/controller.yaml</parameters>
    </plugin>
  </gazebo> -->
  
  <!-- World: LINK -->
  <link name="world"/>

  <!-- Custom colors -->
  <material name="crate_green">
            <color rgba="0.1176 0.6706 0.5373 1.0"/>
        </material>
        <material name="crate_grey">
            <color rgba="0.5 0.5 0.5 1.0"/>
        </material>
        <material name="realsense_alum">
            <color rgba="0.4392 0.4392 0.4392 1.0"/>
  </material>
  <!-- Robot Stand: LINK -->
  <link name="robot_stand">
    <inertial>
      <origin rpy="0 0 0.785398" xyz="0.2829 0 0"/>
      <mass value="100"/>
      <inertia ixx="0.01" ixy="0" ixz="0" iyy="0.01" iyz="0" izz="0.01"/>
    </inertial>
    <collision name="collision">
      <origin rpy=" 0 0 0.785398" xyz="0.2829 0 0"/>
      <geometry>
        <box size="0.8 0.8 0.67"/>
      </geometry>
    </collision>
    <visual name="chassis_visual">
      <origin rpy=" 0 0 0.785398" xyz="0.2829 0 0"/>
      <geometry>
        <box size="0.8 0.8 0.67"/>
      </geometry>
    </visual>
  </link>
  <!-- Robot Stand: FIXED JOINT -->
  <joint name="world_joint" type="fixed">
    <parent link="world"/>
    <child link="robot_stand"/>
    <origin rpy="0.0 0.0 0.0" xyz="0.0 0.0 -0.345"/>
  </joint>
  <!-- Robot Stand: Robot+Stand JOINT -->
  <joint name="stand_joint" type="fixed">
    <parent link="robot_stand"/>
    <child link="base_link"/>
    <origin rpy="0.0 0.0 0.0" xyz="0.0 0.0 0.34"/>
  </joint>


  <!--- Custom added: Crate : LINK -->
  <link name="crate">
      <visual>
        <material name="crate_green"/>
          <geometry>
              <mesh filename="package://abb_irb120_support/meshes/custom/crate.stl"/>
          </geometry>
          <origin rpy="0 0 0" xyz="0 0 0"/>
      </visual>
      <collision>
          <geometry>
              <mesh filename="package://abb_irb120_support/meshes/custom/crate_collision.stl"/>
          </geometry>
          <origin rpy="0 0 0" xyz="0 0 -0.005"/> <!-- Minimal movement down to, the crate collision is slightly higher than the crate for collision-prevention. Slightly reduced due to small setup robotarm reach. -->
      </collision>
  </link>
  <!-- Add the crate_foam link -->
  <link name="crate_foam">
      <visual>
          <material name="crate_grey"/>
          <geometry>
              <mesh filename="package://abb_irb120_support/meshes/custom/crate_foam.stl"/>
          </geometry>
          <origin rpy="0 0 0" xyz="0 0 0"/>
      </visual>
      <collision>
          <geometry>
              <mesh filename="package://abb_irb120_support/meshes/custom/crate_foam.stl"/>
          </geometry>
          <origin rpy="0 0 0" xyz="0 0 0"/>
      </collision>
  </link>
  <!-- Add the crate inner bottom center link -->
  <link name="crate_inner_bottom_center"/>

  <joint name="crate_joint" type="fixed">
      <parent link="robot_stand"/>
      <child link="crate"/>
      <origin rpy="0 0 1.570796" xyz="0.31 0 0.51"/>
  </joint>
  <!-- Add the joint to connect the crate_foam to crate -->
  <joint name="crate_foam_joint" type="fixed">
      <parent link="crate"/>
      <child link="crate_foam"/>
      <origin rpy="0 0 0" xyz="0 0 0"/>
  </joint>
  <!-- Add the joint to connect the crate_inner_bottom_center to crate -->
  <joint name="crate_inner_bottom_center_joint" type="fixed">
      <parent link="crate"/>
      <child link="crate_inner_bottom_center"/>
      <origin rpy="0 0 0" xyz="0 0 -0.143"/>
  </joint>




  <!-- Custom MPZ45 gripper + collision box. -->
  <link name="tool_gripper">
      <visual>
          <material name="crate_grey"/>
          <geometry>
              <mesh filename="package://abb_irb120_support/meshes/custom/collision_tool.stl"/>
          </geometry>
          <origin rpy="0 0 0" xyz="0 0 0"/>
      </visual>
      <collision>
          <geometry>
              <mesh filename="package://abb_irb120_support/meshes/custom/collision_tool.stl"/>
          </geometry>
          <origin rpy="0 0 0" xyz="0 0 0"/>
      </collision>
  </link>

  <joint name="tool_gripper-flange_joint" type="fixed">
    <parent link="flange"/>
    <child link="tool_gripper"/>
    <origin rpy="0 1.5708 0" xyz="0 0 0"/>
  </joint>

  <link name="camera_mount">
      <visual>
          <material name="crate_grey"/>
          <geometry>
              <mesh filename="package://abb_irb120_support/meshes/custom/collision_mount.stl"/>
          </geometry>
          <origin rpy="0 0 0" xyz="0 0 0"/>
      </visual>
      <collision>
          <geometry>
              <mesh filename="package://abb_irb120_support/meshes/custom/collision_mount.stl"/>
          </geometry>
          <origin rpy="0 0 0" xyz="0 0 0"/>
      </collision>
  </link>

  <joint name="camera_mount-link_5" type="fixed">
    <parent link="link_5"/>
    <child link="camera_mount"/>
    <origin rpy="0 1.5708 0" xyz="0.047 0 0"/>
  </joint>

  <!-- Links & joints for tcp's. -->

  <link name="tool_tcp" />
  <link name="camera" />
  <link name="camera_tcp" />

  <joint name="camera-link_5_joint" type="fixed">
    <origin xyz="0.125 0 0.06" rpy="0 0 0" />
    <parent link="link_5" />
    <child link="camera" />
  </joint>

  <joint name="tool_tcp-link_6_joint" type="fixed">
    <origin xyz="0.095 0 0" rpy="0 -1.57079633 0" /> <!-- Rotation fix has been applied here, 90degree turn on the Y axis () -->
    <parent link= "link_6" />
    <child link="tool_tcp" />
  </joint>

  <joint name="camera_tcp-camera_joint" type="fixed">
    <origin xyz="0 -0.0175 0" rpy="0 0 0" />
    <parent link="camera" />
    <child link="camera_tcp" />
  </joint>

<!-- Link and joint for Place center (See abb_irb120_params.yaml in StateMachine). -->
  <link name="place_center" />

  <joint name="place_center-world" type="fixed">
    <origin xyz="0.3 -0.42 0" rpy="0 0 0" />
    <parent link="world" />
    <child link="place_center" />
  </joint>

  <link name="example" />
  <joint name="example-world" type="fixed">
    <origin xyz="0.29 -0.43 0.009250" rpy="3.1415842 0 1.5707963" />
    <parent link="world" />
    <child link="example" />
  </joint>

</robot>